<mujoco model="drawer_articulated_object">
  <!--
    Articulated drawer task object.

    The uploaded drawer CAD (drawer_visual_m.stl) is a single solid drawer block
    with a recessed front-face handle (no protrusion) and NO separate cabinet.
    So here the CAD mesh is the *sliding drawer*, and the cabinet it pulls out of
    is built from primitive boxes. A graspable D-handle is also added as a
    primitive (the CAD recess cannot be pinched).

    The whole object is scaled 2x relative to the raw CAD (mesh scale="2 2 2" and
    all primitive dims doubled) so the drawer and handle are large enough to see
    where the gripper grasps. Raw CAD drawer is 0.070 x 0.095 x 0.060 m -> 2x is
    0.140 x 0.190 x 0.120 m.

    Local frame: z=0 is the cabinet bottom (rests on the table). The drawer opens
    along +y (the front / handle face). The environment rotates the whole object
    (set_euler) so this +y opening faces the robot.
  -->
  <asset>
    <mesh name="drawer_mesh" file="../meshes/drawer_visual_m.stl" scale="2 2 2"/>
    <material name="drawer_mat"  rgba="0.55 0.45 0.35 1" specular="0.25" shininess="0.3"/>
    <material name="cabinet_mat" rgba="0.35 0.33 0.30 1" specular="0.20" shininess="0.2"/>
    <material name="handle_mat"  rgba="0.15 0.15 0.18 1" specular="0.60" shininess="0.6"/>
  </asset>

  <worldbody>
    <body>
      <body name="object">
        <!-- Static cabinet frame (no joint => welded to world). Open on +y. -->
        <body name="frame">
          <geom name="cab_bottom" type="box" pos="0 0 0.008"        size="0.096 0.105 0.008"
                material="cabinet_mat" friction="1 0.01 0.001" group="0"/>
          <geom name="cab_left"   type="box" pos="-0.088 -0.005 0.080" size="0.008 0.100 0.064"
                material="cabinet_mat" friction="1 0.01 0.001" group="0"/>
          <geom name="cab_right"  type="box" pos="0.088 -0.005 0.080"  size="0.008 0.100 0.064"
                material="cabinet_mat" friction="1 0.01 0.001" group="0"/>
          <geom name="cab_back"   type="box" pos="0 -0.113 0.080"  size="0.096 0.008 0.064"
                material="cabinet_mat" friction="1 0.01 0.001" group="0"/>
          <geom name="cab_top"    type="box" pos="0 -0.005 0.152"  size="0.096 0.100 0.008"
                material="cabinet_mat" friction="1 0.01 0.001" group="0"/>
        </body>

        <!-- Sliding drawer: CAD mesh (visual) + box collision + added grasp handle.
             NB: geom/body names must NOT start with the object name ("drawer"), or
             robosuite 1.5.x double-prefixes them (drawer_ + drawer_... ) and crashes. -->
        <body name="tray" pos="0 0 0.018">
          <joint name="slide" type="slide" axis="0 1 0" pos="0 0 0"
                 range="0 0.32" limited="true" damping="2" frictionloss="1" armature="0.02"/>

          <geom name="tray_visual" type="mesh" mesh="drawer_mesh" material="drawer_mat"
                contype="0" conaffinity="0" group="1"/>
          <geom name="tray_collision" type="box" pos="0 0 0.060" size="0.068 0.092 0.058"
                rgba="0.2 0.2 0.2 0" density="200" friction="1 0.01 0.001"
                solimp="0.998 0.998 0.001" solref="0.002 1" group="0"/>

          <!-- Added graspable D-handle protruding from the front (+y) face (not in CAD). -->
          <geom name="handle_post_l" type="box" pos="-0.028 0.102 0.064" size="0.008 0.008 0.012"
                material="handle_mat" friction="1 0.01 0.001" group="1"/>
          <geom name="handle_post_r" type="box" pos="0.028 0.102 0.064"  size="0.008 0.008 0.012"
                material="handle_mat" friction="1 0.01 0.001" group="1"/>
          <geom name="handle" type="cylinder" fromto="-0.036 0.116 0.064 0.036 0.116 0.064" size="0.010"
                material="handle_mat" friction="2 0.05 0.001"
                solimp="0.998 0.998 0.001" solref="0.002 1" group="1"/>

          <site name="handle_site" pos="0 0.116 0.064" size="0.012" rgba="1 0 0 0.3"/>
        </body>
      </body>

      <site name="bottom_site"            pos="0 0 0"        size="0.005" rgba="0 0 0 0"/>
      <site name="top_site"               pos="0 0 0.160"    size="0.005" rgba="0 0 0 0"/>
      <site name="horizontal_radius_site" pos="0.120 0 0.080" size="0.005" rgba="0 0 0 0"/>
    </body>
  </worldbody>
</mujoco>
